{"name": "test_general_user_cannot_send_invite_user_email", "status": "passed", "description": "一般ユーザで正常に招待メールを送信できないことをテスト", "attachments": [{"name": "log", "source": "d7bea02a-b016-42d6-9843-648dd8dc9ac9-attachment.txt", "type": "text/plain"}], "start": 1673748205735, "stop": 1673748205866, "uuid": "59243cd6-4d53-407b-85f3-2219595aeb95", "historyId": "7a58083cbcb99e129ae60247bd35a04d", "testCaseId": "83d35813e67632397909c7ab7ff099a0", "fullName": "application.tests.mail.test_email.TestInviteUser#test_general_user_cannot_send_invite_user_email", "labels": [{"name": "tag", "value": "django_db"}, {"name": "parentSuite", "value": "application.tests.mail"}, {"name": "suite", "value": "test_email"}, {"name": "subSuite", "value": "TestInviteUser"}, {"name": "host", "value": "eab8ab219ba9"}, {"name": "thread", "value": "309-MainThread"}, {"name": "framework", "value": "pytest"}, {"name": "language", "value": "cpython3"}, {"name": "package", "value": "application.tests.mail.test_email"}]}